Workbook

Sheet START HERE
A1: COLLEGE MONEY OS | B1: COLLEGE MONEY OS | C1: COLLEGE MONEY OS | D1: COLLEGE MONEY OS | E1: COLLEGE MONEY OS | F1: COLLEGE MONEY OS | G1: COLLEGE MONEY OS | H1: COLLEGE MONEY OS | I1: COLLEGE MONEY OS | J1: COLLEGE MONEY OS
A2: COLLEGE MONEY OS | B2: COLLEGE MONEY OS | C2: COLLEGE MONEY OS | D2: COLLEGE MONEY OS | E2: COLLEGE MONEY OS | F2: COLLEGE MONEY OS | G2: COLLEGE MONEY OS | H2: COLLEGE MONEY OS | I2: COLLEGE MONEY OS | J2: COLLEGE MONEY OS
A3: A premium, formula-driven finance system for a first-year B.Tech CSE (AI & ML) hostel student. | B3: A premium, formula-driven finance system for a first-year B.Tech CSE (AI & ML) hostel student. | C3: A premium, formula-driven finance system for a first-year B.Tech CSE (AI & ML) hostel student. | D3: A premium, formula-driven finance system for a first-year B.Tech CSE (AI & ML) hostel student. | E3: A premium, formula-driven finance system for a first-year B.Tech CSE (AI & ML) hostel student. | F3: A premium, formula-driven finance system for a first-year B.Tech CSE (AI & ML) hostel student. | G3: A premium, formula-driven finance system for a first-year B.Tech CSE (AI & ML) hostel student. | H3: A premium, formula-driven finance system for a first-year B.Tech CSE (AI & ML) hostel student. | I3: A premium, formula-driven finance system for a first-year B.Tech CSE (AI & ML) hostel student. | J3: A premium, formula-driven finance system for a first-year B.Tech CSE (AI & ML) hostel student.
A5: Get started in 8 simple steps | B5: Get started in 8 simple steps | C5: Get started in 8 simple steps | D5: Get started in 8 simple steps | E5: Get started in 8 simple steps | F5: Get started in 8 simple steps | H5: Color key | I5: Color key | J5: Color key
A7: 1 | B7: Personalize | C7: Open SETTINGS and update the orange profile, year, semester dates and thresholds. | H7: ORANGE | I7: Editable inputs | J7: Type or choose from a dropdown
A8: 2 | B8: Set allowance | C8: Enter your default monthly allowance and savings rule in SETTINGS. | H8: BLUE | I8: Calculated/system | J8: Formula-driven; do not overwrite
A9: 3 | B9: Set budgets | C9: Review the category database and MONTHLY BUDGET. Override any month if needed. | H9: GREEN | I9: Healthy status | J9: On track, paid or reconciled
A10: 4 | B10: Opening balances | C10: Enter opening and actual balances on ACCOUNTS. | H10: RED | I10: Action required | J10: Over budget, overdue or invalid
A11: 5 | B11: Add transactions | C11: Use QUICK ENTRY. Enter each real-world transaction once; blue columns calculate automatically.
A12: 6 | B12: Review | C12: Use DASHBOARD, MONTHLY REPORT and INSIGHTS to spot trends, alerts and safe spending limits.
A13: 7 | B13: Reconcile weekly | C13: Compare calculated vs actual account balances and review duplicates or missing fields.
A14: 8 | B14: Close the month | C14: Complete the checklist and reflection on MONTHLY REPORT; never delete history.
A17: Demo data & privacy | B17: Demo data & privacy | C17: Demo data & privacy | D17: Demo data & privacy | E17: Demo data & privacy | F17: Demo data & privacy | G17: Demo data & privacy | H17: Demo data & privacy | I17: Demo data & privacy | J17: Demo data & privacy
A19: The sample rows on QUICK ENTRY are marked Demo = Yes. Keep Demo Mode = Yes to explore the workbook. Before entering real data, set SETTINGS > Demo Mode to No (demo rows are excluded instantly) or delete those clearly marked rows. Store only harmless account nicknames and transaction values—never bank passwords, UPI/ATM PINs, CVV, OTPs or internet-banking credentials. | B19: The sample rows on QUICK ENTRY are marked Demo = Yes. Keep Demo Mode = Yes to explore the workbook. Before entering real data, set SETTINGS > Demo Mode to No (demo rows are excluded instantly) or delete those clearly marked rows. Store only harmless account nicknames and transaction values—never bank passwords, UPI/ATM PINs, CVV, OTPs or internet-banking credentials. | C19: The sample rows on QUICK ENTRY are marked Demo = Yes. Keep Demo Mode = Yes to explore the workbook. Before entering real data, set SETTINGS > Demo Mode to No (demo rows are excluded instantly) or delete those clearly marked rows. Store only harmless account nicknames and transaction values—never bank passwords, UPI/ATM PINs, CVV, OTPs or internet-banking credentials. | D19: The sample rows on QUICK ENTRY are marked Demo = Yes. Keep Demo Mode = Yes to explore the workbook. Before entering real data, set SETTINGS > Demo Mode to No (demo rows are excluded instantly) or delete those clearly marked rows. Store only harmless account nicknames and transaction values—never bank passwords, UPI/ATM PINs, CVV, OTPs or internet-banking credentials. | E19: The sample rows on QUICK ENTRY are marked Demo = Yes. Keep Demo Mode = Yes to explore the workbook. Before entering real data, set SETTINGS > Demo Mode to No (demo rows are excluded instantly) or delete those clearly marked rows. Store only harmless account nicknames and transaction values—never bank passwords, UPI/ATM PINs, CVV, OTPs or internet-banking credentials. | F19: The sample rows on QUICK ENTRY are marked Demo = Yes. Keep Demo Mode = Yes to explore the workbook. Before entering real data, set SETTINGS > Demo Mode to No (demo rows are excluded instantly) or delete those clearly marked rows. Store only harmless account nicknames and transaction values—never bank passwords, UPI/ATM PINs, CVV, OTPs or internet-banking credentials. | G19: The sample rows on QUICK ENTRY are marked Demo = Yes. Keep Demo Mode = Yes to explore the workbook. Before entering real data, set SETTINGS > Demo Mode to No (demo rows are excluded instantly) or delete those clearly marked rows. Store only harmless account nicknames and transaction values—never bank passwords, UPI/ATM PINs, CVV, OTPs or internet-banking credentials. | H19: The sample rows on QUICK ENTRY are marked Demo = Yes. Keep Demo Mode = Yes to explore the workbook. Before entering real data, set SETTINGS > Demo Mode to No (demo rows are excluded instantly) or delete those clearly marked rows. Store only harmless account nicknames and transaction values—never bank passwords, UPI/ATM PINs, CVV, OTPs or internet-banking credentials. | I19: The sample rows on QUICK ENTRY are marked Demo = Yes. Keep Demo Mode = Yes to explore the workbook. Before entering real data, set SETTINGS > Demo Mode to No (demo rows are excluded instantly) or delete those clearly marked rows. Store only harmless account nicknames and transaction values—never bank passwords, UPI/ATM PINs, CVV, OTPs or internet-banking credentials. | J19: The sample rows on QUICK ENTRY are marked Demo = Yes. Keep Demo Mode = Yes to explore the workbook. Before entering real data, set SETTINGS > Demo Mode to No (demo rows are excluded instantly) or delete those clearly marked rows. Store only harmless account nicknames and transaction values—never bank passwords, UPI/ATM PINs, CVV, OTPs or internet-banking credentials.
A20: The sample rows on QUICK ENTRY are marked Demo = Yes. Keep Demo Mode = Yes to explore the workbook. Before entering real data, set SETTINGS > Demo Mode to No (demo rows are excluded instantly) or delete those clearly marked rows. Store only harmless account nicknames and transaction values—never bank passwords, UPI/ATM PINs, CVV, OTPs or internet-banking credentials. | B20: The sample rows on QUICK ENTRY are marked Demo = Yes. Keep Demo Mode = Yes to explore the workbook. Before entering real data, set SETTINGS > Demo Mode to No (demo rows are excluded instantly) or delete those clearly marked rows. Store only harmless account nicknames and transaction values—never bank passwords, UPI/ATM PINs, CVV, OTPs or internet-banking credentials. | C20: The sample rows on QUICK ENTRY are marked Demo = Yes. Keep Demo Mode = Yes to explore the workbook. Before entering real data, set SETTINGS > Demo Mode to No (demo rows are excluded instantly) or delete those clearly marked rows. Store only harmless account nicknames and transaction values—never bank passwords, UPI/ATM PINs, CVV, OTPs or internet-banking credentials. | D20: The sample rows on QUICK ENTRY are marked Demo = Yes. Keep Demo Mode = Yes to explore the workbook. Before entering real data, set SETTINGS > Demo Mode to No (demo rows are excluded instantly) or delete those clearly marked rows. Store only harmless account nicknames and transaction values—never bank passwords, UPI/ATM PINs, CVV, OTPs or internet-banking credentials. | E20: The sample rows on QUICK ENTRY are marked Demo = Yes. Keep Demo Mode = Yes to explore the workbook. Before entering real data, set SETTINGS > Demo Mode to No (demo rows are excluded instantly) or delete those clearly marked rows. Store only harmless account nicknames and transaction values—never bank passwords, UPI/ATM PINs, CVV, OTPs or internet-banking credentials. | F20: The sample rows on QUICK ENTRY are marked Demo = Yes. Keep Demo Mode = Yes to explore the workbook. Before entering real data, set SETTINGS > Demo Mode to No (demo rows are excluded instantly) or delete those clearly marked rows. Store only harmless account nicknames and transaction values—never bank passwords, UPI/ATM PINs, CVV, OTPs or internet-banking credentials. | G20: The sample rows on QUICK ENTRY are marked Demo = Yes. Keep Demo Mode = Yes to explore the workbook. Before entering real data, set SETTINGS > Demo Mode to No (demo rows are excluded instantly) or delete those clearly marked rows. Store only harmless account nicknames and transaction values—never bank passwords, UPI/ATM PINs, CVV, OTPs or internet-banking credentials. | H20: The sample rows on QUICK ENTRY are marked Demo = Yes. Keep Demo Mode = Yes to explore the workbook. Before entering real data, set SETTINGS > Demo Mode to No (demo rows are excluded instantly) or delete those clearly marked rows. Store only harmless account nicknames and transaction values—never bank passwords, UPI/ATM PINs, CVV, OTPs or internet-banking credentials. | I20: The sample rows on QUICK ENTRY are marked Demo = Yes. Keep Demo Mode = Yes to explore the workbook. Before entering real data, set SETTINGS > Demo Mode to No (demo rows are excluded instantly) or delete those clearly marked rows. Store only harmless account nicknames and transaction values—never bank passwords, UPI/ATM PINs, CVV, OTPs or internet-banking credentials. | J20: The sample rows on QUICK ENTRY are marked Demo = Yes. Keep Demo Mode = Yes to explore the workbook. Before entering real data, set SETTINGS > Demo Mode to No (demo rows are excluded instantly) or delete those clearly marked rows. Store only harmless account nicknames and transaction values—never bank passwords, UPI/ATM PINs, CVV, OTPs or internet-banking credentials.
A21: The sample rows on QUICK ENTRY are marked Demo = Yes. Keep Demo Mode = Yes to explore the workbook. Before entering real data, set SETTINGS > Demo Mode to No (demo rows are excluded instantly) or delete those clearly marked rows. Store only harmless account nicknames and transaction values—never bank passwords, UPI/ATM PINs, CVV, OTPs or internet-banking credentials. | B21: The sample rows on QUICK ENTRY are marked Demo = Yes. Keep Demo Mode = Yes to explore the workbook. Before entering real data, set SETTINGS > Demo Mode to No (demo rows are excluded instantly) or delete those clearly marked rows. Store only harmless account nicknames and transaction values—never bank passwords, UPI/ATM PINs, CVV, OTPs or internet-banking credentials. | C21: The sample rows on QUICK ENTRY are marked Demo = Yes. Keep Demo Mode = Yes to explore the workbook. Before entering real data, set SETTINGS > Demo Mode to No (demo rows are excluded instantly) or delete those clearly marked rows. Store only harmless account nicknames and transaction values—never bank passwords, UPI/ATM PINs, CVV, OTPs or internet-banking credentials. | D21: The sample rows on QUICK ENTRY are marked Demo = Yes. Keep Demo Mode = Yes to explore the workbook. Before entering real data, set SETTINGS > Demo Mode to No (demo rows are excluded instantly) or delete those clearly marked rows. Store only harmless account nicknames and transaction values—never bank passwords, UPI/ATM PINs, CVV, OTPs or internet-banking credentials. | E21: The sample rows on QUICK ENTRY are marked Demo = Yes. Keep Demo Mode = Yes to explore the workbook. Before entering real data, set SETTINGS > Demo Mode to No (demo rows are excluded instantly) or delete those clearly marked rows. Store only harmless account nicknames and transaction values—never bank passwords, UPI/ATM PINs, CVV, OTPs or internet-banking credentials. | F21: The sample rows on QUICK ENTRY are marked Demo = Yes. Keep Demo Mode = Yes to explore the workbook. Before entering real data, set SETTINGS > Demo Mode to No (demo rows are excluded instantly) or delete those clearly marked rows. Store only harmless account nicknames and transaction values—never bank passwords, UPI/ATM PINs, CVV, OTPs or internet-banking credentials. | G21: The sample rows on QUICK ENTRY are marked Demo = Yes. Keep Demo Mode = Yes to explore the workbook. Before entering real data, set SETTINGS > Demo Mode to No (demo rows are excluded instantly) or delete those clearly marked rows. Store only harmless account nicknames and transaction values—never bank passwords, UPI/ATM PINs, CVV, OTPs or internet-banking credentials. | H21: The sample rows on QUICK ENTRY are marked Demo = Yes. Keep Demo Mode = Yes to explore the workbook. Before entering real data, set SETTINGS > Demo Mode to No (demo rows are excluded instantly) or delete those clearly marked rows. Store only harmless account nicknames and transaction values—never bank passwords, UPI/ATM PINs, CVV, OTPs or internet-banking credentials. | I21: The sample rows on QUICK ENTRY are marked Demo = Yes. Keep Demo Mode = Yes to explore the workbook. Before entering real data, set SETTINGS > Demo Mode to No (demo rows are excluded instantly) or delete those clearly marked rows. Store only harmless account nicknames and transaction values—never bank passwords, UPI/ATM PINs, CVV, OTPs or internet-banking credentials. | J21: The sample rows on QUICK ENTRY are marked Demo = Yes. Keep Demo Mode = Yes to explore the workbook. Before entering real data, set SETTINGS > Demo Mode to No (demo rows are excluded instantly) or delete those clearly marked rows. Store only harmless account nicknames and transaction values—never bank passwords, UPI/ATM PINs, CVV, OTPs or internet-banking credentials.
A24: How the workbook flows | B24: How the workbook flows | C24: How the workbook flows | D24: How the workbook flows | E24: How the workbook flows | F24: How the workbook flows | G24: How the workbook flows | H24: How the workbook flows | I24: How the workbook flows | J24: How the workbook flows
A26: QUICK ENTRY (one master table) → MONTHLY BUDGET → DASHBOARD / REPORTS / INSIGHTS → ACCOUNTS / GOALS / FORECASTS Specialized tabs are planners and analyses. Record actual money movement only once in QUICK ENTRY to avoid double-counting. | B26: QUICK ENTRY (one master table) → MONTHLY BUDGET → DASHBOARD / REPORTS / INSIGHTS → ACCOUNTS / GOALS / FORECASTS Specialized tabs are planners and analyses. Record actual money movement only once in QUICK ENTRY to avoid double-counting. | C26: QUICK ENTRY (one master table) → MONTHLY BUDGET → DASHBOARD / REPORTS / INSIGHTS → ACCOUNTS / GOALS / FORECASTS Specialized tabs are planners and analyses. Record actual money movement only once in QUICK ENTRY to avoid double-counting. | D26: QUICK ENTRY (one master table) → MONTHLY BUDGET → DASHBOARD / REPORTS / INSIGHTS → ACCOUNTS / GOALS / FORECASTS Specialized tabs are planners and analyses. Record actual money movement only once in QUICK ENTRY to avoid double-counting. | E26: QUICK ENTRY (one master table) → MONTHLY BUDGET → DASHBOARD / REPORTS / INSIGHTS → ACCOUNTS / GOALS / FORECASTS Specialized tabs are planners and analyses. Record actual money movement only once in QUICK ENTRY to avoid double-counting. | F26: QUICK ENTRY (one master table) → MONTHLY BUDGET → DASHBOARD / REPORTS / INSIGHTS → ACCOUNTS / GOALS / FORECASTS Specialized tabs are planners and analyses. Record actual money movement only once in QUICK ENTRY to avoid double-counting. | G26: QUICK ENTRY (one master table) → MONTHLY BUDGET → DASHBOARD / REPORTS / INSIGHTS → ACCOUNTS / GOALS / FORECASTS Specialized tabs are planners and analyses. Record actual money movement only once in QUICK ENTRY to avoid double-counting. | H26: QUICK ENTRY (one master table) → MONTHLY BUDGET → DASHBOARD / REPORTS / INSIGHTS → ACCOUNTS / GOALS / FORECASTS Specialized tabs are planners and analyses. Record actual money movement only once in QUICK ENTRY to avoid double-counting. | I26: QUICK ENTRY (one master table) → MONTHLY BUDGET → DASHBOARD / REPORTS / INSIGHTS → ACCOUNTS / GOALS / FORECASTS Specialized tabs are planners and analyses. Record actual money movement only once in QUICK ENTRY to avoid double-counting. | J26: QUICK ENTRY (one master table) → MONTHLY BUDGET → DASHBOARD / REPORTS / INSIGHTS → ACCOUNTS / GOALS / FORECASTS Specialized tabs are planners and analyses. Record actual money movement only once in QUICK ENTRY to avoid double-counting.
A27: QUICK ENTRY (one master table) → MONTHLY BUDGET → DASHBOARD / REPORTS / INSIGHTS → ACCOUNTS / GOALS / FORECASTS Specialized tabs are planners and analyses. Record actual money movement only once in QUICK ENTRY to avoid double-counting. | B27: QUICK ENTRY (one master table) → MONTHLY BUDGET → DASHBOARD / REPORTS / INSIGHTS → ACCOUNTS / GOALS / FORECASTS Specialized tabs are planners and analyses. Record actual money movement only once in QUICK ENTRY to avoid double-counting. | C27: QUICK ENTRY (one master table) → MONTHLY BUDGET → DASHBOARD / REPORTS / INSIGHTS → ACCOUNTS / GOALS / FORECASTS Specialized tabs are planners and analyses. Record actual money movement only once in QUICK ENTRY to avoid double-counting. | D27: QUICK ENTRY (one master table) → MONTHLY BUDGET → DASHBOARD / REPORTS / INSIGHTS → ACCOUNTS / GOALS / FORECASTS Specialized tabs are planners and analyses. Record actual money movement only once in QUICK ENTRY to avoid double-counting. | E27: QUICK ENTRY (one master table) → MONTHLY BUDGET → DASHBOARD / REPORTS / INSIGHTS → ACCOUNTS / GOALS / FORECASTS Specialized tabs are planners and analyses. Record actual money movement only once in QUICK ENTRY to avoid double-counting. | F27: QUICK ENTRY (one master table) → MONTHLY BUDGET → DASHBOARD / REPORTS / INSIGHTS → ACCOUNTS / GOALS / FORECASTS Specialized tabs are planners and analyses. Record actual money movement only once in QUICK ENTRY to avoid double-counting. | G27: QUICK ENTRY (one master table) → MONTHLY BUDGET → DASHBOARD / REPORTS / INSIGHTS → ACCOUNTS / GOALS / FORECASTS Specialized tabs are planners and analyses. Record actual money movement only once in QUICK ENTRY to avoid double-counting. | H27: QUICK ENTRY (one master table) → MONTHLY BUDGET → DASHBOARD / REPORTS / INSIGHTS → ACCOUNTS / GOALS / FORECASTS Specialized tabs are planners and analyses. Record actual money movement only once in QUICK ENTRY to avoid double-counting. | I27: QUICK ENTRY (one master table) → MONTHLY BUDGET → DASHBOARD / REPORTS / INSIGHTS → ACCOUNTS / GOALS / FORECASTS Specialized tabs are planners and analyses. Record actual money movement only once in QUICK ENTRY to avoid double-counting. | J27: QUICK ENTRY (one master table) → MONTHLY BUDGET → DASHBOARD / REPORTS / INSIGHTS → ACCOUNTS / GOALS / FORECASTS Specialized tabs are planners and analyses. Record actual money movement only once in QUICK ENTRY to avoid double-counting.
A28: QUICK ENTRY (one master table) → MONTHLY BUDGET → DASHBOARD / REPORTS / INSIGHTS → ACCOUNTS / GOALS / FORECASTS Specialized tabs are planners and analyses. Record actual money movement only once in QUICK ENTRY to avoid double-counting. | B28: QUICK ENTRY (one master table) → MONTHLY BUDGET → DASHBOARD / REPORTS / INSIGHTS → ACCOUNTS / GOALS / FORECASTS Specialized tabs are planners and analyses. Record actual money movement only once in QUICK ENTRY to avoid double-counting. | C28: QUICK ENTRY (one master table) → MONTHLY BUDGET → DASHBOARD / REPORTS / INSIGHTS → ACCOUNTS / GOALS / FORECASTS Specialized tabs are planners and analyses. Record actual money movement only once in QUICK ENTRY to avoid double-counting. | D28: QUICK ENTRY (one master table) → MONTHLY BUDGET → DASHBOARD / REPORTS / INSIGHTS → ACCOUNTS / GOALS / FORECASTS Specialized tabs are planners and analyses. Record actual money movement only once in QUICK ENTRY to avoid double-counting. | E28: QUICK ENTRY (one master table) → MONTHLY BUDGET → DASHBOARD / REPORTS / INSIGHTS → ACCOUNTS / GOALS / FORECASTS Specialized tabs are planners and analyses. Record actual money movement only once in QUICK ENTRY to avoid double-counting. | F28: QUICK ENTRY (one master table) → MONTHLY BUDGET → DASHBOARD / REPORTS / INSIGHTS → ACCOUNTS / GOALS / FORECASTS Specialized tabs are planners and analyses. Record actual money movement only once in QUICK ENTRY to avoid double-counting. | G28: QUICK ENTRY (one master table) → MONTHLY BUDGET → DASHBOARD / REPORTS / INSIGHTS → ACCOUNTS / GOALS / FORECASTS Specialized tabs are planners and analyses. Record actual money movement only once in QUICK ENTRY to avoid double-counting. | H28: QUICK ENTRY (one master table) → MONTHLY BUDGET → DASHBOARD / REPORTS / INSIGHTS → ACCOUNTS / GOALS / FORECASTS Specialized tabs are planners and analyses. Record actual money movement only once in QUICK ENTRY to avoid double-counting. | I28: QUICK ENTRY (one master table) → MONTHLY BUDGET → DASHBOARD / REPORTS / INSIGHTS → ACCOUNTS / GOALS / FORECASTS Specialized tabs are planners and analyses. Record actual money movement only once in QUICK ENTRY to avoid double-counting. | J28: QUICK ENTRY (one master table) → MONTHLY BUDGET → DASHBOARD / REPORTS / INSIGHTS → ACCOUNTS / GOALS / FORECASTS Specialized tabs are planners and analyses. Record actual money movement only once in QUICK ENTRY to avoid double-counting.

Sheet DASHBOARD
A1: PERSONAL FINANCE DASHBOARD | B1: PERSONAL FINANCE DASHBOARD | C1: PERSONAL FINANCE DASHBOARD | D1: PERSONAL FINANCE DASHBOARD | E1: PERSONAL FINANCE DASHBOARD | F1: PERSONAL FINANCE DASHBOARD | G1: PERSONAL FINANCE DASHBOARD | H1: PERSONAL FINANCE DASHBOARD | I1: PERSONAL FINANCE DASHBOARD | J1: PERSONAL FINANCE DASHBOARD | K1: PERSONAL FINANCE DASHBOARD | L1: PERSONAL FINANCE DASHBOARD | M1: PERSONAL FINANCE DASHBOARD | N1: PERSONAL FINANCE DASHBOARD | O1: PERSONAL FINANCE DASHBOARD | P1: PERSONAL FINANCE DASHBOARD
A2: PERSONAL FINANCE DASHBOARD | B2: PERSONAL FINANCE DASHBOARD | C2: PERSONAL FINANCE DASHBOARD | D2: PERSONAL FINANCE DASHBOARD | E2: PERSONAL FINANCE DASHBOARD | F2: PERSONAL FINANCE DASHBOARD | G2: PERSONAL FINANCE DASHBOARD | H2: PERSONAL FINANCE DASHBOARD | I2: PERSONAL FINANCE DASHBOARD | J2: PERSONAL FINANCE DASHBOARD | K2: PERSONAL FINANCE DASHBOARD | L2: PERSONAL FINANCE DASHBOARD | M2: PERSONAL FINANCE DASHBOARD | N2: PERSONAL FINANCE DASHBOARD | O2: PERSONAL FINANCE DASHBOARD | P2: PERSONAL FINANCE DASHBOARD
A3: Month | B3: Month | C3: September | D3: September | E3: Selected month KPIs, alerts, trends and forecasts. Change only the orange controls below. | F3: ="Viewing "&$C$3&" "&TEXT($C$4,"0")&" • Demo Mode: "&SETTINGS!$B$16 -> Viewing September 2026 • Demo Mode: Yes | G3: Selected month KPIs, alerts, trends and forecasts. Change only the orange controls below. | H3: Selected month KPIs, alerts, trends and forecasts. Change only the orange controls below. | I3: Selected month KPIs, alerts, trends and forecasts. Change only the orange controls below. | J3: Selected month KPIs, alerts, trends and forecasts. Change only the orange controls below. | K3: Selected month KPIs, alerts, trends and forecasts. Change only the orange controls below. | L3: Selected month KPIs, alerts, trends and forecasts. Change only the orange controls below. | M3: Selected month KPIs, alerts, trends and forecasts. Change only the orange controls below. | N3: Selected month KPIs, alerts, trends and forecasts. Change only the orange controls below. | O3: Selected month KPIs, alerts, trends and forecasts. Change only the orange controls below. | P3: Selected month KPIs, alerts, trends and forecasts. Change only the orange controls below. | R3: Category | S3: Actual | U3: Month | V3: Income | W3: Expense | Y3: Month | Z3: Cumulative Savings | AB3: Cost Type | AC3: Actual | AE3: Payment Method | AF3: Spend
A4: Planning Year | B4: Planning Year | C4: 2026 | D4: 2026 | R4: =$A27 -> College Fees | S4: =IF($R4="Savings",0,$C27) -> 0 | U4: ='ANNUAL SUMMARY'!$A$8 -> January | V4: ='ANNUAL SUMMARY'!$C$8 -> 25000 | W4: ='ANNUAL SUMMARY'!$E$8 -> 8000 | Y4: ='ANNUAL SUMMARY'!$A$8 -> January | Z4: ='ANNUAL SUMMARY'!$T$8 -> 0 | AB4: Fixed | AC4: =SUMIF('MONTHLY BUDGET'!$C$8:$C$27,AB4,'MONTHLY BUDGET'!$T$8:$T$27) -> 3748 | AE4: Cash | AF4: =SUMIFS('QUICK ENTRY'!$E$8:$E$1007,'QUICK ENTRY'!$AF$8:$AF$1007,"Yes",'QUICK ENTRY'!$C$8:$C$1007,"Expense",'QUICK ENTRY'!$V$8:$V$1007,$C$3,'QUICK ENTRY'!$X$8:$X$1007,$C$4,'QUICK ENTRY'!$F$8:$F$1007,AE4) -> 280
R5: =$A28 -> Hostel | S5: =IF($R5="Savings",0,$C28) -> 3200 | U5: ='ANNUAL SUMMARY'!$A$9 -> February | V5: ='ANNUAL SUMMARY'!$C$9 -> 25000 | W5: ='ANNUAL SUMMARY'!$E$9 -> 4400 | Y5: ='ANNUAL SUMMARY'!$A$9 -> February | Z5: ='ANNUAL SUMMARY'!$T$9 -> 0 | AB5: Variable | AC5: =SUMIF('MONTHLY BUDGET'!$C$8:$C$27,AB5,'MONTHLY BUDGET'!$T$8:$T$27) -> 3449 | AE5: UPI | AF5: =SUMIFS('QUICK ENTRY'!$E$8:$E$1007,'QUICK ENTRY'!$AF$8:$AF$1007,"Yes",'QUICK ENTRY'!$C$8:$C$1007,"Expense",'QUICK ENTRY'!$V$8:$V$1007,$C$3,'QUICK ENTRY'!$X$8:$X$1007,$C$4,'QUICK ENTRY'!$F$8:$F$1007,AE5) -> 4448
A6: TOTAL MONEY RECEIVED | B6: TOTAL MONEY RECEIVED | C6: TOTAL MONEY RECEIVED | D6: TOTAL MONEY RECEIVED | E6: TOTAL SPENT | F6: TOTAL SPENT | G6: TOTAL SPENT | H6: TOTAL SPENT | I6: REMAINING BALANCE | J6: REMAINING BALANCE | K6: REMAINING BALANCE | L6: REMAINING BALANCE | M6: TOTAL SAVED | N6: TOTAL SAVED | O6: TOTAL SAVED | P6: TOTAL SAVED | R6: =$A29 -> Food | S6: =IF($R6="Savings",0,$C29) -> 620 | U6: ='ANNUAL SUMMARY'!$A$10 -> March | V6: ='ANNUAL SUMMARY'!$C$10 -> 25000 | W6: ='ANNUAL SUMMARY'!$E$10 -> 3099 | Y6: ='ANNUAL SUMMARY'!$A$10 -> March | Z6: ='ANNUAL SUMMARY'!$T$10 -> 0 | AB6: Savings | AC6: =SUMIF('MONTHLY BUDGET'!$C$8:$C$27,AB6,'MONTHLY BUDGET'!$T$8:$T$27) -> 2500 | AE6: GPay | AF6: =SUMIFS('QUICK ENTRY'!$E$8:$E$1007,'QUICK ENTRY'!$AF$8:$AF$1007,"Yes",'QUICK ENTRY'!$C$8:$C$1007,"Expense",'QUICK ENTRY'!$V$8:$V$1007,$C$3,'QUICK ENTRY'!$X$8:$X$1007,$C$4,'QUICK ENTRY'!$F$8:$F$1007,AE6) -> 620
A7: TOTAL MONEY RECEIVED | B7: TOTAL MONEY RECEIVED | C7: TOTAL MONEY RECEIVED | D7: TOTAL MONEY RECEIVED | E7: TOTAL SPENT | F7: TOTAL SPENT | G7: TOTAL SPENT | H7: TOTAL SPENT | I7: REMAINING BALANCE | J7: REMAINING BALANCE | K7: REMAINING BALANCE | L7: REMAINING BALANCE | M7: TOTAL SAVED | N7: TOTAL SAVED | O7: TOTAL SAVED | P7: TOTAL SAVED | R7: =$A30 -> Transport | S7: =IF($R7="Savings",0,$C30) -> 350 | U7: ='ANNUAL SUMMARY'!$A$11 -> April | V7: ='ANNUAL SUMMARY'!$C$11 -> 25000 | W7: ='ANNUAL SUMMARY'!$E$11 -> 4900 | Y7: ='ANNUAL SUMMARY'!$A$11 -> April | Z7: ='ANNUAL SUMMARY'!$T$11 -> 0 | AE7: PhonePe | AF7: =SUMIFS('QUICK ENTRY'!$E$8:$E$1007,'QUICK ENTRY'!$AF$8:$AF$1007,"Yes",'QUICK ENTRY'!$C$8:$C$1007,"Expense",'QUICK ENTRY'!$V$8:$V$1007,$C$3,'QUICK ENTRY'!$X$8:$X$1007,$C$4,'QUICK ENTRY'!$F$8:$F$1007,AE7) -> 350
A8: =SUMIFS('QUICK ENTRY'!$E$8:$E$1007,'QUICK ENTRY'!$AF$8:$AF$1007,"Yes",'QUICK ENTRY'!$C$8:$C$1007,"Income",'QUICK ENTRY'!$V$8:$V$1007,DASHBOARD!$C$3,'QUICK ENTRY'!$X$8:$X$1007,DASHBOARD!$C$4)+SUMIFS('QUICK ENTRY'!$E$8:$E$1007,'QUICK ENTRY'!$AF$8:$AF$1007,"Yes",'QUICK ENTRY'!$C$8:$C$1007,"Refund",'QUICK ENTRY'!$V$8:$V$1007,DASHBOARD!$C$3,'QUICK ENTRY'!$X$8:$X$1007,DASHBOARD!$C$4)+SUMIFS('QUICK ENTRY'!$E$8:$E$1007,'QUICK ENTRY'!$AF$8:$AF$1007,"Yes",'QUICK ENTRY'!$C$8:$C$1007,"Reimbursement",'QUICK ENTRY'!$V$8:$V$1007,DASHBOARD!$C$3,'QUICK ENTRY'!$X$8:$X$1007,DASHBOARD!$C$4) -> 25000 | E8: =SUMIFS('QUICK ENTRY'!$E$8:$E$1007,'QUICK ENTRY'!$AF$8:$AF$1007,"Yes",'QUICK ENTRY'!$C$8:$C$1007,"Expense",'QUICK ENTRY'!$V$8:$V$1007,DASHBOARD!$C$3,'QUICK ENTRY'!$X$8:$X$1007,DASHBOARD!$C$4) -> 7197 | I8: =A8-E8-M8 -> 15303 | M8: =SUMIFS('QUICK ENTRY'!$E$8:$E$1007,'QUICK ENTRY'!$AF$8:$AF$1007,"Yes",'QUICK ENTRY'!$C$8:$C$1007,"Savings Transfer",'QUICK ENTRY'!$V$8:$V$1007,DASHBOARD!$C$3,'QUICK ENTRY'!$X$8:$X$1007,DASHBOARD!$C$4) -> 2500 | R8: =$A31 -> Technology | S8: =IF($R8="Savings",0,$C31) -> 0 | U8: ='ANNUAL SUMMARY'!$A$12 -> May | V8: ='ANNUAL SUMMARY'!$C$12 -> 25000 | W8: ='ANNUAL SUMMARY'!$E$12 -> 3300 | Y8: ='ANNUAL SUMMARY'!$A$12 -> May | Z8: ='ANNUAL SUMMARY'!$T$12 -> 0 | AE8: Paytm | AF8: =SUMIFS('QUICK ENTRY'!$E$8:$E$1007,'QUICK ENTRY'!$AF$8:$AF$1007,"Yes",'QUICK ENTRY'!$C$8:$C$1007,"Expense",'QUICK ENTRY'!$V$8:$V$1007,$C$3,'QUICK ENTRY'!$X$8:$X$1007,$C$4,'QUICK ENTRY'!$F$8:$F$1007,AE8) -> 0
R9: =$A32 -> AI-ML Learning | S9: =IF($R9="Savings",0,$C32) -> 1499 | U9: ='ANNUAL SUMMARY'!$A$13 -> June | V9: ='ANNUAL SUMMARY'!$C$13 -> 25000 | W9: ='ANNUAL SUMMARY'!$E$13 -> 2649 | Y9: ='ANNUAL SUMMARY'!$A$13 -> June | Z9: ='ANNUAL SUMMARY'!$T$13 -> 0 | AE9: Debit Card | AF9: =SUMIFS('QUICK ENTRY'!$E$8:$E$1007,'QUICK ENTRY'!$AF$8:$AF$1007,"Yes",'QUICK ENTRY'!$C$8:$C$1007,"Expense",'QUICK ENTRY'!$V$8:$V$1007,$C$3,'QUICK ENTRY'!$X$8:$X$1007,$C$4,'QUICK ENTRY'!$F$8:$F$1007,AE9) -> 1499
R10: =$A33 -> Books & Stationery | S10: =IF($R10="Savings",0,$C33) -> 280 | U10: ='ANNUAL SUMMARY'!$A$14 -> July | V10: ='ANNUAL SUMMARY'!$C$14 -> 25000 | W10: ='ANNUAL SUMMARY'!$E$14 -> 8200 | Y10: ='ANNUAL SUMMARY'!$A$14 -> July | Z10: ='ANNUAL SUMMARY'!$T$14 -> 0 | AE10: Credit Card | AF10: =SUMIFS('QUICK ENTRY'!$E$8:$E$1007,'QUICK ENTRY'!$AF$8:$AF$1007,"Yes",'QUICK ENTRY'!$C$8:$C$1007,"Expense",'QUICK ENTRY'!$V$8:$V$1007,$C$3,'QUICK ENTRY'!$X$8:$X$1007,$C$4,'QUICK ENTRY'!$F$8:$F$1007,AE10) -> 0
A11: SAVINGS RATE | B11: SAVINGS RATE | C11: SAVINGS RATE | D11: SAVINGS RATE | E11: BUDGET USED | F11: BUDGET USED | G11: BUDGET USED | H11: BUDGET USED | I11: EMERGENCY FUND | J11: EMERGENCY FUND | K11: EMERGENCY FUND | L11: EMERGENCY FUND | M11: FINANCIAL SCORE | N11: FINANCIAL SCORE | O11: FINANCIAL SCORE | P11: FINANCIAL SCORE | R11: =$A34 -> Subscriptions | S11: =IF($R11="Savings",0,$C34) -> 199 | U11: ='ANNUAL SUMMARY'!$A$15 -> August | V11: ='ANNUAL SUMMARY'!$C$15 -> 30000 | W11: ='ANNUAL SUMMARY'!$E$15 -> 5200 | Y11: ='ANNUAL SUMMARY'!$A$15 -> August | Z11: ='ANNUAL SUMMARY'!$T$15 -> 2000 | AE11: Bank Transfer | AF11: =SUMIFS('QUICK ENTRY'!$E$8:$E$1007,'QUICK ENTRY'!$AF$8:$AF$1007,"Yes",'QUICK ENTRY'!$C$8:$C$1007,"Expense",'QUICK ENTRY'!$V$8:$V$1007,$C$3,'QUICK ENTRY'!$X$8:$X$1007,$C$4,'QUICK ENTRY'!$F$8:$F$1007,AE11) -> 0
A12: SAVINGS RATE | B12: SAVINGS RATE | C12: SAVINGS RATE | D12: SAVINGS RATE | E12: BUDGET USED | F12: BUDGET USED | G12: BUDGET USED | H12: BUDGET USED | I12: EMERGENCY FUND | J12: EMERGENCY FUND | K12: EMERGENCY FUND | L12: EMERGENCY FUND | M12: FINANCIAL SCORE | N12: FINANCIAL SCORE | O12: FINANCIAL SCORE | P12: FINANCIAL SCORE | R12: =$A35 -> Mobile & Internet | S12: =IF($R12="Savings",0,$C35) -> 349 | U12: ='ANNUAL SUMMARY'!$A$16 -> September | V12: ='ANNUAL SUMMARY'!$C$16 -> 25000 | W12: ='ANNUAL SUMMARY'!$E$16 -> 7197 | Y12: ='ANNUAL SUMMARY'!$A$16 -> September | Z12: ='ANNUAL SUMMARY'!$T$16 -> 4500
A13: =IFERROR(M8/A8,0) -> 0.1 | E13: =IFERROR((E8+M8)/'MONTHLY BUDGET'!$S$28,0) -> 0.36592453 | I13: ='EMERGENCY FUND'!$B$8 -> 9500 | M13: =INSIGHTS!$B$8 -> 83 | R13: =$A36 -> Personal Care | S13: =IF($R13="Savings",0,$C36) -> 0 | U13: ='ANNUAL SUMMARY'!$A$17 -> October | V13: ='ANNUAL SUMMARY'!$C$17 -> 0 | W13: ='ANNUAL SUMMARY'!$E$17 -> 0 | Y13: ='ANNUAL SUMMARY'!$A$17 -> October | Z13: ='ANNUAL SUMMARY'!$T$17 -> 4500
R14: =$A37 -> Clothing | S14: =IF($R14="Savings",0,$C37) -> 0 | U14: ='ANNUAL SUMMARY'!$A$18 -> November | V14: ='ANNUAL SUMMARY'!$C$18 -> 0 | W14: ='ANNUAL SUMMARY'!$E$18 -> 0 | Y14: ='ANNUAL SUMMARY'!$A$18 -> November | Z14: ='ANNUAL SUMMARY'!$T$18 -> 4500
R15: =$A38 -> Entertainment | S15: =IF($R15="Savings",0,$C38) -> 0 | U15: ='ANNUAL SUMMARY'!$A$19 -> December | V15: ='ANNUAL SUMMARY'!$C$19 -> 0 | W15: ='ANNUAL SUMMARY'!$E$19 -> 0 | Y15: ='ANNUAL SUMMARY'!$A$19 -> December | Z15: ='ANNUAL SUMMARY'!$T$19 -> 4500
A16: AVERAGE DAILY SPEND | B16: AVERAGE DAILY SPEND | C16: AVERAGE DAILY SPEND | D16: AVERAGE DAILY SPEND | E16: SAFE SPENDING TODAY | F16: SAFE SPENDING TODAY | G16: SAFE SPENDING TODAY | H16: SAFE SPENDING TODAY | I16: PROJECTED MONTH-END BALANCE | J16: PROJECTED MONTH-END BALANCE | K16: PROJECTED MONTH-END BALANCE | L16: PROJECTED MONTH-END BALANCE | M16: UPCOMING BILLS (7 DAYS) | N16: UPCOMING BILLS (7 DAYS) | O16: UPCOMING BILLS (7 DAYS) | P16: UPCOMING BILLS (7 DAYS) | R16: =$A39 -> Travel Home | S16: =IF($R16="Savings",0,$C39) -> 0
A17: AVERAGE DAILY SPEND | B17: AVERAGE DAILY SPEND | C17: AVERAGE DAILY SPEND | D17: AVERAGE DAILY SPEND | E17: SAFE SPENDING TODAY | F17: SAFE SPENDING TODAY | G17: SAFE SPENDING TODAY | H17: SAFE SPENDING TODAY | I17: PROJECTED MONTH-END BALANCE | J17: PROJECTED MONTH-END BALANCE | K17: PROJECTED MONTH-END BALANCE | L17: PROJECTED MONTH-END BALANCE | M17: UPCOMING BILLS (7 DAYS) | N17: UPCOMING BILLS (7 DAYS) | O17: UPCOMING BILLS (7 DAYS) | P17: UPCOMING BILLS (7 DAYS) | R17: =$A40 -> Health & Fitness | S17: =IF($R17="Savings",0,$C40) -> 700
A18: ='MONTHLY BUDGET'!$B$37 -> 239.9 | E18: ='MONTHLY BUDGET'!$B$43 -> 16803 | I18: ='MONTHLY BUDGET'!$B$44 -> 15303 | M18: =COUNTIFS('QUICK ENTRY'!$AF$8:$AF$1007,"Yes",'QUICK ENTRY'!$O$8:$O$1007,"<>Paid",'QUICK ENTRY'!$P$8:$P$1007,">="&TODAY(),'QUICK ENTRY'!$P$8:$P$1007,"<="&TODAY()+SETTINGS!$E$8) -> 0 | R18: =$A41 -> Shopping & Gifts | S18: =IF($R18="Savings",0,$C41) -> 0
R19: =$A42 -> Emergency | S19: =IF($R19="Savings",0,$C42) -> 0
R20: =$A43 -> Savings | S20: =IF($R20="Savings",0,$C43) -> 0
A21: =IF(E13>1,"Monthly budget exceeded by INR "&TEXT((E8+M8)-'MONTHLY BUDGET'!$S$28,"#,##0"),IF(E13>0.9,"Near budget limit — only INR "&TEXT('MONTHLY BUDGET'!$U$28,"#,##0")&" remains",IF('MONTHLY BUDGET'!$W$28>'MONTHLY BUDGET'!$S$28,"Projected spending may exceed budget",IF(I8<SETTINGS!$B$17,"Available balance is below the minimum safe level","You are within budget. Safe to spend INR "&TEXT(E18,"#,##0")&" today.")))) -> You are within budget. Safe to spend INR 16,803 today. | R21: =$A44 -> Miscellaneous | S21: =IF($R21="Savings",0,$C44) -> 0
R22: =$A45 -> Shared Expenses | S22: =IF($R22="Savings",0,$C45) -> 0
R23: =$A46 -> Career | S23: =IF($R23="Savings",0,$C46) -> 0
A26: Category | B26: Budget | C26: Actual | D26: Remaining | E26: % Used | F26: Status
A27: ='MONTHLY BUDGET'!$A$8 -> College Fees | B27: ='MONTHLY BUDGET'!$S$8 -> 4500 | C27: ='MONTHLY BUDGET'!$T$8 -> 0 | D27: ='MONTHLY BUDGET'!$U$8 -> 4500 | E27: ='MONTHLY BUDGET'!$V$8 -> 0 | F27: ='MONTHLY BUDGET'!$X$8 -> Safe
A28: ='MONTHLY BUDGET'!$A$9 -> Hostel | B28: ='MONTHLY BUDGET'!$S$9 -> 3500 | C28: ='MONTHLY BUDGET'!$T$9 -> 3200 | D28: ='MONTHLY BUDGET'!$U$9 -> 300 | E28: ='MONTHLY BUDGET'!$V$9 -> 0.91428571 | F28: ='MONTHLY BUDGET'!$X$9 -> Near Limit
A29: ='MONTHLY BUDGET'!$A$10 -> Food | B29: ='MONTHLY BUDGET'!$S$10 -> 4000 | C29: ='MONTHLY BUDGET'!$T$10 -> 620 | D29: ='MONTHLY BUDGET'!$U$10 -> 3380 | E29: ='MONTHLY BUDGET'!$V$10 -> 0.155 | F29: ='MONTHLY BUDGET'!$X$10 -> Safe
A30: ='MONTHLY BUDGET'!$A$11 -> Transport | B30: ='MONTHLY BUDGET'!$S$11 -> 1500 | C30: ='MONTHLY BUDGET'!$T$11 -> 350 | D30: ='MONTHLY BUDGET'!$U$11 -> 1150 | E30: ='MONTHLY BUDGET'!$V$11 -> 0.23333333 | F30: ='MONTHLY BUDGET'!$X$11 -> Safe
A31: ='MONTHLY BUDGET'!$A$12 -> Technology | B31: ='MONTHLY BUDGET'!$S$12 -> 1500 | C31: ='MONTHLY BUDGET'!$T$12 -> 0 | D31: ='MONTHLY BUDGET'!$U$12 -> 1500 | E31: ='MONTHLY BUDGET'!$V$12 -> 0 | F31: ='MONTHLY BUDGET'!$X$12 -> Safe
A32: ='MONTHLY BUDGET'!$A$13 -> AI-ML Learning | B32: ='MONTHLY BUDGET'!$S$13 -> 1000 | C32: ='MONTHLY BUDGET'!$T$13 -> 1499 | D32: ='MONTHLY BUDGET'!$U$13 -> -499 | E32: ='MONTHLY BUDGET'!$V$13 -> 1.499 | F32: ='MONTHLY BUDGET'!$X$13 -> Over Budget
A33: ='MONTHLY BUDGET'!$A$14 -> Books & Stationery | B33: ='MONTHLY BUDGET'!$S$14 -> 500 | C33: ='MONTHLY BUDGET'!$T$14 -> 280 | D33: ='MONTHLY BUDGET'!$U$14 -> 220 | E33: ='MONTHLY BUDGET'!$V$14 -> 0.56 | F33: ='MONTHLY BUDGET'!$X$14 -> Safe
A34: ='MONTHLY BUDGET'!$A$15 -> Subscriptions | B34: ='MONTHLY BUDGET'!$S$15 -> 600 | C34: ='MONTHLY BUDGET'!$T$15 -> 199 | D34: ='MONTHLY BUDGET'!$U$15 -> 401 | E34: ='MONTHLY BUDGET'!$V$15 -> 0.33166667 | F34: ='MONTHLY BUDGET'!$X$15 -> Safe
A35: ='MONTHLY BUDGET'!$A$16 -> Mobile & Internet | B35: ='MONTHLY BUDGET'!$S$16 -> 400 | C35: ='MONTHLY BUDGET'!$T$16 -> 349 | D35: ='MONTHLY BUDGET'!$U$16 -> 51 | E35: ='MONTHLY BUDGET'!$V$16 -> 0.8725 | F35: ='MONTHLY BUDGET'!$X$16 -> Watch Spending
A36: ='MONTHLY BUDGET'!$A$17 -> Personal Care | B36: ='MONTHLY BUDGET'!$S$17 -> 500 | C36: ='MONTHLY BUDGET'!$T$17 -> 0 | D36: ='MONTHLY BUDGET'!$U$17 -> 500 | E36: ='MONTHLY BUDGET'!$V$17 -> 0 | F36: ='MONTHLY BUDGET'!$X$17 -> Safe
A37: ='MONTHLY BUDGET'!$A$18 -> Clothing | B37: ='MONTHLY BUDGET'!$S$18 -> 500 | C37: ='MONTHLY BUDGET'!$T$18 -> 0 | D37: ='MONTHLY BUDGET'!$U$18 -> 500 | E37: ='MONTHLY BUDGET'!$V$18 -> 0 | F37: ='MONTHLY BUDGET'!$X$18 -> Safe
A38: ='MONTHLY BUDGET'!$A$19 -> Entertainment | B38: ='MONTHLY BUDGET'!$S$19 -> 1000 | C38: ='MONTHLY BUDGET'!$T$19 -> 0 | D38: ='MONTHLY BUDGET'!$U$19 -> 1000 | E38: ='MONTHLY BUDGET'!$V$19 -> 0 | F38: ='MONTHLY BUDGET'!$X$19 -> Safe
A39: ='MONTHLY BUDGET'!$A$20 -> Travel Home | B39: ='MONTHLY BUDGET'!$S$20 -> 1000 | C39: ='MONTHLY BUDGET'!$T$20 -> 0 | D39: ='MONTHLY BUDGET'!$U$20 -> 1000 | E39: ='MONTHLY BUDGET'!$V$20 -> 0 | F39: ='MONTHLY BUDGET'!$X$20 -> Safe
A40: ='MONTHLY BUDGET'!$A$21 -> Health & Fitness | B40: ='MONTHLY BUDGET'!$S$21 -> 700 | C40: ='MONTHLY BUDGET'!$T$21 -> 700 | D40: ='MONTHLY BUDGET'!$U$21 -> 0 | E40: ='MONTHLY BUDGET'!$V$21 -> 1 | F40: ='MONTHLY BUDGET'!$X$21 -> Near Limit
A41: ='MONTHLY BUDGET'!$A$22 -> Shopping & Gifts | B41: ='MONTHLY BUDGET'!$S$22 -> 1000 | C41: ='MONTHLY BUDGET'!$T$22 -> 0 | D41: ='MONTHLY BUDGET'!$U$22 -> 1000 | E41: ='MONTHLY BUDGET'!$V$22 -> 0 | F41: ='MONTHLY BUDGET'!$X$22 -> Safe
A42: ='MONTHLY BUDGET'!$A$23 -> Emergency | B42: ='MONTHLY BUDGET'!$S$23 -> 500 | C42: ='MONTHLY BUDGET'!$T$23 -> 0 | D42: ='MONTHLY BUDGET'!$U$23 -> 500 | E42: ='MONTHLY BUDGET'!$V$23 -> 0 | F42: ='MONTHLY BUDGET'!$X$23 -> Safe
...

Sheet QUICK ENTRY
A1: QUICK ENTRY · MASTER TRANSACTIONS | B1: QUICK ENTRY · MASTER TRANSACTIONS | C1: QUICK ENTRY · MASTER TRANSACTIONS | D1: QUICK ENTRY · MASTER TRANSACTIONS | E1: QUICK ENTRY · MASTER TRANSACTIONS | F1: QUICK ENTRY · MASTER TRANSACTIONS | G1: QUICK ENTRY · MASTER TRANSACTIONS | H1: QUICK ENTRY · MASTER TRANSACTIONS | I1: QUICK ENTRY · MASTER TRANSACTIONS | J1: QUICK ENTRY · MASTER TRANSACTIONS | K1: QUICK ENTRY · MASTER TRANSACTIONS | L1: QUICK ENTRY · MASTER TRANSACTIONS | M1: QUICK ENTRY · MASTER TRANSACTIONS | N1: QUICK ENTRY · MASTER TRANSACTIONS | O1: QUICK ENTRY · MASTER TRANSACTIONS | P1: QUICK ENTRY · MASTER TRANSACTIONS | Q1: QUICK ENTRY · MASTER TRANSACTIONS | R1: QUICK ENTRY · MASTER TRANSACTIONS | S1: QUICK ENTRY · MASTER TRANSACTIONS | T1: QUICK ENTRY · MASTER TRANSACTIONS | U1: QUICK ENTRY · MASTER TRANSACTIONS | V1: QUICK ENTRY · MASTER TRANSACTIONS | W1: QUICK ENTRY · MASTER TRANSACTIONS | X1: QUICK ENTRY · MASTER TRANSACTIONS | Y1: QUICK ENTRY · MASTER TRANSACTIONS | Z1: QUICK ENTRY · MASTER TRANSACTIONS | AA1: QUICK ENTRY · MASTER TRANSACTIONS | AB1: QUICK ENTRY · MASTER TRANSACTIONS | AC1: QUICK ENTRY · MASTER TRANSACTIONS | AD1: QUICK ENTRY · MASTER TRANSACTIONS | AE1: QUICK ENTRY · MASTER TRANSACTIONS | AF1: QUICK ENTRY · MASTER TRANSACTIONS | AG1: QUICK ENTRY · MASTER TRANSACTIONS
A2: QUICK ENTRY · MASTER TRANSACTIONS | B2: QUICK ENTRY · MASTER TRANSACTIONS | C2: QUICK ENTRY · MASTER TRANSACTIONS | D2: QUICK ENTRY · MASTER TRANSACTIONS | E2: QUICK ENTRY · MASTER TRANSACTIONS | F2: QUICK ENTRY · MASTER TRANSACTIONS | G2: QUICK ENTRY · MASTER TRANSACTIONS | H2: QUICK ENTRY · MASTER TRANSACTIONS | I2: QUICK ENTRY · MASTER TRANSACTIONS | J2: QUICK ENTRY · MASTER TRANSACTIONS | K2: QUICK ENTRY · MASTER TRANSACTIONS | L2: QUICK ENTRY · MASTER TRANSACTIONS | M2: QUICK ENTRY · MASTER TRANSACTIONS | N2: QUICK ENTRY · MASTER TRANSACTIONS | O2: QUICK ENTRY · MASTER TRANSACTIONS | P2: QUICK ENTRY · MASTER TRANSACTIONS | Q2: QUICK ENTRY · MASTER TRANSACTIONS | R2: QUICK ENTRY · MASTER TRANSACTIONS | S2: QUICK ENTRY · MASTER TRANSACTIONS | T2: QUICK ENTRY · MASTER TRANSACTIONS | U2: QUICK ENTRY · MASTER TRANSACTIONS | V2: QUICK ENTRY · MASTER TRANSACTIONS | W2: QUICK ENTRY · MASTER TRANSACTIONS | X2: QUICK ENTRY · MASTER TRANSACTIONS | Y2: QUICK ENTRY · MASTER TRANSACTIONS | Z2: QUICK ENTRY · MASTER TRANSACTIONS | AA2: QUICK ENTRY · MASTER TRANSACTIONS | AB2: QUICK ENTRY · MASTER TRANSACTIONS | AC2: QUICK ENTRY · MASTER TRANSACTIONS | AD2: QUICK ENTRY · MASTER TRANSACTIONS | AE2: QUICK ENTRY · MASTER TRANSACTIONS | AF2: QUICK ENTRY · MASTER TRANSACTIONS | AG2: QUICK ENTRY · MASTER TRANSACTIONS
A3: Enter each transaction once. Keep the first seven columns together for phone-friendly entry; blue fields calculate automatically. | B3: Enter each transaction once. Keep the first seven columns together for phone-friendly entry; blue fields calculate automatically. | C3: Enter each transaction once. Keep the first seven columns together for phone-friendly entry; blue fields calculate automatically. | D3: Enter each transaction once. Keep the first seven columns together for phone-friendly entry; blue fields calculate automatically. | E3: Enter each transaction once. Keep the first seven columns together for phone-friendly entry; blue fields calculate automatically. | F3: Enter each transaction once. Keep the first seven columns together for phone-friendly entry; blue fields calculate automatically. | G3: Enter each transaction once. Keep the first seven columns together for phone-friendly entry; blue fields calculate automatically. | H3: Enter each transaction once. Keep the first seven columns together for phone-friendly entry; blue fields calculate automatically. | I3: Enter each transaction once. Keep the first seven columns together for phone-friendly entry; blue fields calculate automatically. | J3: Enter each transaction once. Keep the first seven columns together for phone-friendly entry; blue fields calculate automatically. | K3: Enter each transaction once. Keep the first seven columns together for phone-friendly entry; blue fields calculate automatically. | L3: Enter each transaction once. Keep the first seven columns together for phone-friendly entry; blue fields calculate automatically. | M3: Enter each transaction once. Keep the first seven columns together for phone-friendly entry; blue fields calculate automatically. | N3: Enter each transaction once. Keep the first seven columns together for phone-friendly entry; blue fields calculate automatically. | O3: Enter each transaction once. Keep the first seven columns together for phone-friendly entry; blue fields calculate automatically. | P3: Enter each transaction once. Keep the first seven columns together for phone-friendly entry; blue fields calculate automatically. | Q3: Enter each transaction once. Keep the first seven columns together for phone-friendly entry; blue fields calculate automatically. | R3: Enter each transaction once. Keep the first seven columns together for phone-friendly entry; blue fields calculate automatically. | S3: Enter each transaction once. Keep the first seven columns together for phone-friendly entry; blue fields calculate automatically. | T3: Enter each transaction once. Keep the first seven columns together for phone-friendly entry; blue fields calculate automatically. | U3: Enter each transaction once. Keep the first seven columns together for phone-friendly entry; blue fields calculate automatically. | V3: Enter each transaction once. Keep the first seven columns together for phone-friendly entry; blue fields calculate automatically. | W3: Enter each transaction once. Keep the first seven columns together for phone-friendly entry; blue fields calculate automatically. | X3: Enter each transaction once. Keep the first seven columns together for phone-friendly entry; blue fields calculate automatically. | Y3: Enter each transaction once. Keep the first seven columns together for phone-friendly entry; blue fields calculate automatically. | Z3: Enter each transaction once. Keep the first seven columns together for phone-friendly entry; blue fields calculate automatically. | AA3: Enter each transaction once. Keep the first seven columns together for phone-friendly entry; blue fields calculate automatically. | AB3: Enter each transaction once. Keep the first seven columns together for phone-friendly entry; blue fields calculate automatically. | AC3: Enter each transaction once. Keep the first seven columns together for phone-friendly entry; blue fields calculate automatically. | AD3: Enter each transaction once. Keep the first seven columns together for phone-friendly entry; blue fields calculate automatically. | AE3: Enter each transaction once. Keep the first seven columns together for phone-friendly entry; blue fields calculate automatically. | AF3: Enter each transaction once. Keep the first seven columns together for phone-friendly entry; blue fields calculate automatically. | AG3: Enter each transaction once. Keep the first seven columns together for phone-friendly entry; blue fields calculate automatically.
A5: CORE INPUTS — complete these first | B5: CORE INPUTS — complete these first | C5: CORE INPUTS — complete these first | D5: CORE INPUTS — complete these first | E5: CORE INPUTS — complete these first | F5: CORE INPUTS — complete these first | G5: CORE INPUTS — complete these first | H5: OPTIONAL DETAILS + AUTOMATIC SYSTEM FIELDS | I5: OPTIONAL DETAILS + AUTOMATIC SYSTEM FIELDS | J5: OPTIONAL DETAILS + AUTOMATIC SYSTEM FIELDS | K5: OPTIONAL DETAILS + AUTOMATIC SYSTEM FIELDS | L5: OPTIONAL DETAILS + AUTOMATIC SYSTEM FIELDS | M5: OPTIONAL DETAILS + AUTOMATIC SYSTEM FIELDS | N5: OPTIONAL DETAILS + AUTOMATIC SYSTEM FIELDS | O5: OPTIONAL DETAILS + AUTOMATIC SYSTEM FIELDS | P5: OPTIONAL DETAILS + AUTOMATIC SYSTEM FIELDS | Q5: OPTIONAL DETAILS + AUTOMATIC SYSTEM FIELDS | R5: OPTIONAL DETAILS + AUTOMATIC SYSTEM FIELDS | S5: OPTIONAL DETAILS + AUTOMATIC SYSTEM FIELDS | T5: OPTIONAL DETAILS + AUTOMATIC SYSTEM FIELDS | U5: OPTIONAL DETAILS + AUTOMATIC SYSTEM FIELDS | V5: OPTIONAL DETAILS + AUTOMATIC SYSTEM FIELDS | W5: OPTIONAL DETAILS + AUTOMATIC SYSTEM FIELDS | X5: OPTIONAL DETAILS + AUTOMATIC SYSTEM FIELDS | Y5: OPTIONAL DETAILS + AUTOMATIC SYSTEM FIELDS | Z5: OPTIONAL DETAILS + AUTOMATIC SYSTEM FIELDS | AA5: OPTIONAL DETAILS + AUTOMATIC SYSTEM FIELDS | AB5: OPTIONAL DETAILS + AUTOMATIC SYSTEM FIELDS | AC5: OPTIONAL DETAILS + AUTOMATIC SYSTEM FIELDS | AD5: OPTIONAL DETAILS + AUTOMATIC SYSTEM FIELDS | AE5: OPTIONAL DETAILS + AUTOMATIC SYSTEM FIELDS | AF5: OPTIONAL DETAILS + AUTOMATIC SYSTEM FIELDS | AG5: OPTIONAL DETAILS + AUTOMATIC SYSTEM FIELDS
A7: Include? | B7: Date | C7: Type | D7: Description | E7: Amount | F7: Payment Method | G7: Category Override | H7: Suggested Category | I7: Final Category | J7: Subcategory | K7: Merchant / Vendor | L7: Account | M7: Need / Want | N7: Recurring? | O7: Payment Status | P7: Due Date | Q7: Paid By | R7: Semester | S7: Tag | T7: Planned Amount | U7: Transaction ID | V7: Month | W7: Month No | X7: Year | Y7: Day | Z7: Day Type | AA7: Duplicate Check | AB7: Unusual Check | AC7: Demo? | AD7: Notes | AE7: Receipt / File Link | AF7: Report? | AG7: Data Quality
A8: Yes | B8: 46023 | C8: Income | D8: Monthly Allowance - January | E8: 25000 | F8: UPI | G8: Miscellaneous | H8: =IF(D8="","",IF(ISNUMBER(SEARCH(SETTINGS!$K$4,D8)),SETTINGS!$L$4,IF(ISNUMBER(SEARCH(SETTINGS!$K$5,D8)),SETTINGS!$L$5,IF(ISNUMBER(SEARCH(SETTINGS!$K$6,D8)),SETTINGS!$L$6,IF(ISNUMBER(SEARCH(SETTINGS!$K$7,D8)),SETTINGS!$L$7,IF(ISNUMBER(SEARCH(SETTINGS!$K$8,D8)),SETTINGS!$L$8,IF(ISNUMBER(SEARCH(SETTINGS!$K$9,D8)),SETTINGS!$L$9,IF(ISNUMBER(SEARCH(SETTINGS!$K$10,D8)),SETTINGS!$L$10,IF(ISNUMBER(SEARCH(SETTINGS!$K$11,D8)),SETTINGS!$L$11,IF(ISNUMBER(SEARCH(SETTINGS!$K$12,D8)),SETTINGS!$L$12,IF(ISNUMBER(SEARCH(SETTINGS!$K$13,D8)),SETTINGS!$L$13,IF(ISNUMBER(SEARCH(SETTINGS!$K$14,D8)),SETTINGS!$L$14,IF(ISNUMBER(SEARCH(SETTINGS!$K$15,D8)),SETTINGS!$L$15,IF(ISNUMBER(SEARCH(SETTINGS!$K$16,D8)),SETTINGS!$L$16,IF(ISNUMBER(SEARCH(SETTINGS!$K$17,D8)),SETTINGS!$L$17,IF(ISNUMBER(SEARCH(SETTINGS!$K$18,D8)),SETTINGS!$L$18,"Miscellaneous")))))))))))))))) -> Miscellaneous | I8: =IF(B8="","",IF(G8<>"",G8,H8)) -> Miscellaneous | J8: Monthly Allowance | L8: UPI-linked Bank | M8: Essential | N8: Recurring | O8: Paid | Q8: Self | R8: Not Applicable | S8: Home | U8: =IF(B8="","",IF(C8="Income","INC-",IF(C8="Expense","EXP-","TRX-"))&TEXT(YEAR(B8),"0000")&"-"&TEXT(ROW()-7,"0000")) -> INC-2026-0001 | V8: =IF(B8="","",TEXT(B8,"mmmm")) -> January | W8: =IF(B8="","",MONTH(B8)) -> 1 | X8: =IF(B8="","",YEAR(B8)) -> 2026 | Y8: =IF(B8="","",DAY(B8)) -> 1 | Z8: =IF(B8="","",IF(WEEKDAY(B8,2)>5,"Weekend","Weekday")) -> Weekday | AA8: =IF(B8="","",IF(COUNTIFS($B$8:$B$1007,B8,$E$8:$E$1007,E8,$D$8:$D$1007,D8,$I$8:$I$1007,I8)>1,"Possible Duplicate","OK")) -> OK | AB8: =IF(OR(B8="",C8<>"Expense"),"",IF(E8>IFERROR(AVERAGEIFS($E$8:$E$1007,$I$8:$I$1007,I8,$C$8:$C$1007,"Expense")*SETTINGS!$B$20,0),"Unusually High","Normal")) | AC8: Yes | AF8: =IF(A8<>"Yes","No",IF(AND(AC8="Yes",SETTINGS!$B$16="No"),"No","Yes")) -> Yes | AG8: =IF(A8<>"Yes","",IF(OR(B8="",D8="",E8<=0,F8="",I8=""),"Check Required Fields",IF(AA8="Possible Duplicate","Possible Duplicate",IF(E8>SETTINGS!$B$22,"Review Extreme Value","OK")))) -> OK
A9: Yes | B9: 46027 | C9: Expense | D9: Semester tuition installment | E9: 4500 | F9: Bank Transfer | G9: College Fees | H9: =IF(D9="","",IF(ISNUMBER(SEARCH(SETTINGS!$K$4,D9)),SETTINGS!$L$4,IF(ISNUMBER(SEARCH(SETTINGS!$K$5,D9)),SETTINGS!$L$5,IF(ISNUMBER(SEARCH(SETTINGS!$K$6,D9)),SETTINGS!$L$6,IF(ISNUMBER(SEARCH(SETTINGS!$K$7,D9)),SETTINGS!$L$7,IF(ISNUMBER(SEARCH(SETTINGS!$K$8,D9)),SETTINGS!$L$8,IF(ISNUMBER(SEARCH(SETTINGS!$K$9,D9)),SETTINGS!$L$9,IF(ISNUMBER(SEARCH(SETTINGS!$K$10,D9)),SETTINGS!$L$10,IF(ISNUMBER(SEARCH(SETTINGS!$K$11,D9)),SETTINGS!$L$11,IF(ISNUMBER(SEARCH(SETTINGS!$K$12,D9)),SETTINGS!$L$12,IF(ISNUMBER(SEARCH(SETTINGS!$K$13,D9)),SETTINGS!$L$13,IF(ISNUMBER(SEARCH(SETTINGS!$K$14,D9)),SETTINGS!$L$14,IF(ISNUMBER(SEARCH(SETTINGS!$K$15,D9)),SETTINGS!$L$15,IF(ISNUMBER(SEARCH(SETTINGS!$K$16,D9)),SETTINGS!$L$16,IF(ISNUMBER(SEARCH(SETTINGS!$K$17,D9)),SETTINGS!$L$17,IF(ISNUMBER(SEARCH(SETTINGS!$K$18,D9)),SETTINGS!$L$18,"Miscellaneous")))))))))))))))) -> College Fees | I9: =IF(B9="","",IF(G9<>"",G9,H9)) -> College Fees | J9: Tuition | K9: College | L9: UPI-linked Bank | M9: Essential | N9: One-Time | O9: Paid | Q9: Parents | R9: Semester 1 | S9: College | U9: =IF(B9="","",IF(C9="Income","INC-",IF(C9="Expense","EXP-","TRX-"))&TEXT(YEAR(B9),"0000")&"-"&TEXT(ROW()-7,"0000")) -> EXP-2026-0002 | V9: =IF(B9="","",TEXT(B9,"mmmm")) -> January | W9: =IF(B9="","",MONTH(B9)) -> 1 | X9: =IF(B9="","",YEAR(B9)) -> 2026 | Y9: =IF(B9="","",DAY(B9)) -> 5 | Z9: =IF(B9="","",IF(WEEKDAY(B9,2)>5,"Weekend","Weekday")) -> Weekday | AA9: =IF(B9="","",IF(COUNTIFS($B$8:$B$1007,B9,$E$8:$E$1007,E9,$D$8:$D$1007,D9,$I$8:$I$1007,I9)>1,"Possible Duplicate","OK")) -> OK | AB9: =IF(OR(B9="",C9<>"Expense"),"",IF(E9>IFERROR(AVERAGEIFS($E$8:$E$1007,$I$8:$I$1007,I9,$C$8:$C$1007,"Expense")*SETTINGS!$B$20,0),"Unusually High","Normal")) -> Normal | AC9: Yes | AF9: =IF(A9<>"Yes","No",IF(AND(AC9="Yes",SETTINGS!$B$16="No"),"No","Yes")) -> Yes | AG9: =IF(A9<>"Yes","",IF(OR(B9="",D9="",E9<=0,F9="",I9=""),"Check Required Fields",IF(AA9="Possible Duplicate","Possible Duplicate",IF(E9>SETTINGS!$B$22,"Review Extreme Value","OK")))) -> OK
A10: Yes | B10: 46030 | C10: Expense | D10: Hostel Fee | E10: 3500 | F10: Bank Transfer | G10: Hostel | H10: =IF(D10="","",IF(ISNUMBER(SEARCH(SETTINGS!$K$4,D10)),SETTINGS!$L$4,IF(ISNUMBER(SEARCH(SETTINGS!$K$5,D10)),SETTINGS!$L$5,IF(ISNUMBER(SEARCH(SETTINGS!$K$6,D10)),SETTINGS!$L$6,IF(ISNUMBER(SEARCH(SETTINGS!$K$7,D10)),SETTINGS!$L$7,IF(ISNUMBER(SEARCH(SETTINGS!$K$8,D10)),SETTINGS!$L$8,IF(ISNUMBER(SEARCH(SETTINGS!$K$9,D10)),SETTINGS!$L$9,IF(ISNUMBER(SEARCH(SETTINGS!$K$10,D10)),SETTINGS!$L$10,IF(ISNUMBER(SEARCH(SETTINGS!$K$11,D10)),SETTINGS!$L$11,IF(ISNUMBER(SEARCH(SETTINGS!$K$12,D10)),SETTINGS!$L$12,IF(ISNUMBER(SEARCH(SETTINGS!$K$13,D10)),SETTINGS!$L$13,IF(ISNUMBER(SEARCH(SETTINGS!$K$14,D10)),SETTINGS!$L$14,IF(ISNUMBER(SEARCH(SETTINGS!$K$15,D10)),SETTINGS!$L$15,IF(ISNUMBER(SEARCH(SETTINGS!$K$16,D10)),SETTINGS!$L$16,IF(ISNUMBER(SEARCH(SETTINGS!$K$17,D10)),SETTINGS!$L$17,IF(ISNUMBER(SEARCH(SETTINGS!$K$18,D10)),SETTINGS!$L$18,"Miscellaneous")))))))))))))))) -> Miscellaneous | I10: =IF(B10="","",IF(G10<>"",G10,H10)) -> Hostel | J10: Hostel Fee | K10: College Hostel | L10: UPI-linked Bank | M10: Essential | N10: One-Time | O10: Paid | Q10: Parents | R10: Semester 1 | S10: Hostel | U10: =IF(B10="","",IF(C10="Income","INC-",IF(C10="Expense","EXP-","TRX-"))&TEXT(YEAR(B10),"0000")&"-"&TEXT(ROW()-7,"0000")) -> EXP-2026-0003 | V10: =IF(B10="","",TEXT(B10,"mmmm")) -> January | W10: =IF(B10="","",MONTH(B10)) -> 1 | X10: =IF(B10="","",YEAR(B10)) -> 2026 | Y10: =IF(B10="","",DAY(B10)) -> 8 | Z10: =IF(B10="","",IF(WEEKDAY(B10,2)>5,"Weekend","Weekday")) -> Weekday | AA10: =IF(B10="","",IF(COUNTIFS($B$8:$B$1007,B10,$E$8:$E$1007,E10,$D$8:$D$1007,D10,$I$8:$I$1007,I10)>1,"Possible Duplicate","OK")) -> OK | AB10: =IF(OR(B10="",C10<>"Expense"),"",IF(E10>IFERROR(AVERAGEIFS($E$8:$E$1007,$I$8:$I$1007,I10,$C$8:$C$1007,"Expense")*SETTINGS!$B$20,0),"Unusually High","Normal")) -> Normal | AC10: Yes | AF10: =IF(A10<>"Yes","No",IF(AND(AC10="Yes",SETTINGS!$B$16="No"),"No","Yes")) -> Yes | AG10: =IF(A10<>"Yes","",IF(OR(B10="",D10="",E10<=0,F10="",I10=""),"Check Required Fields",IF(AA10="Possible Duplicate","Possible Duplicate",IF(E10>SETTINGS!$B$22,"Review Extreme Value","OK")))) -> OK
A11: Yes | B11: 46054 | C11: Income | D11: Monthly Allowance - February | E11: 25000 | F11: UPI | G11: Miscellaneous | H11: =IF(D11="","",IF(ISNUMBER(SEARCH(SETTINGS!$K$4,D11)),SETTINGS!$L$4,IF(ISNUMBER(SEARCH(SETTINGS!$K$5,D11)),SETTINGS!$L$5,IF(ISNUMBER(SEARCH(SETTINGS!$K$6,D11)),SETTINGS!$L$6,IF(ISNUMBER(SEARCH(SETTINGS!$K$7,D11)),SETTINGS!$L$7,IF(ISNUMBER(SEARCH(SETTINGS!$K$8,D11)),SETTINGS!$L$8,IF(ISNUMBER(SEARCH(SETTINGS!$K$9,D11)),SETTINGS!$L$9,IF(ISNUMBER(SEARCH(SETTINGS!$K$10,D11)),SETTINGS!$L$10,IF(ISNUMBER(SEARCH(SETTINGS!$K$11,D11)),SETTINGS!$L$11,IF(ISNUMBER(SEARCH(SETTINGS!$K$12,D11)),SETTINGS!$L$12,IF(ISNUMBER(SEARCH(SETTINGS!$K$13,D11)),SETTINGS!$L$13,IF(ISNUMBER(SEARCH(SETTINGS!$K$14,D11)),SETTINGS!$L$14,IF(ISNUMBER(SEARCH(SETTINGS!$K$15,D11)),SETTINGS!$L$15,IF(ISNUMBER(SEARCH(SETTINGS!$K$16,D11)),SETTINGS!$L$16,IF(ISNUMBER(SEARCH(SETTINGS!$K$17,D11)),SETTINGS!$L$17,IF(ISNUMBER(SEARCH(SETTINGS!$K$18,D11)),SETTINGS!$L$18,"Miscellaneous")))))))))))))))) -> Miscellaneous | I11: =IF(B11="","",IF(G11<>"",G11,H11)) -> Miscellaneous | J11: Monthly Allowance | L11: UPI-linked Bank | M11: Essential | N11: Recurring | O11: Paid | Q11: Self | R11: Not Applicable | S11: Home | U11: =IF(B11="","",IF(C11="Income","INC-",IF(C11="Expense","EXP-","TRX-"))&TEXT(YEAR(B11),"0000")&"-"&TEXT(ROW()-7,"0000")) -> INC-2026-0004 | V11: =IF(B11="","",TEXT(B11,"mmmm")) -> February | W11: =IF(B11="","",MONTH(B11)) -> 2 | X11: =IF(B11="","",YEAR(B11)) -> 2026 | Y11: =IF(B11="","",DAY(B11)) -> 1 | Z11: =IF(B11="","",IF(WEEKDAY(B11,2)>5,"Weekend","Weekday")) -> Weekend | AA11: =IF(B11="","",IF(COUNTIFS($B$8:$B$1007,B11,$E$8:$E$1007,E11,$D$8:$D$1007,D11,$I$8:$I$1007,I11)>1,"Possible Duplicate","OK")) -> OK | AB11: =IF(OR(B11="",C11<>"Expense"),"",IF(E11>IFERROR(AVERAGEIFS($E$8:$E$1007,$I$8:$I$1007,I11,$C$8:$C$1007,"Expense")*SETTINGS!$B$20,0),"Unusually High","Normal")) | AC11: Yes | AF11: =IF(A11<>"Yes","No",IF(AND(AC11="Yes",SETTINGS!$B$16="No"),"No","Yes")) -> Yes | AG11: =IF(A11<>"Yes","",IF(OR(B11="",D11="",E11<=0,F11="",I11=""),"Check Required Fields",IF(AA11="Possible Duplicate","Possible Duplicate",IF(E11>SETTINGS!$B$22,"Review Extreme Value","OK")))) -> OK
A12: Yes | B12: 46065 | C12: Expense | D12: Groceries and fruit | E12: 3200 | F12: UPI | G12: Food | H12: =IF(D12="","",IF(ISNUMBER(SEARCH(SETTINGS!$K$4,D12)),SETTINGS!$L$4,IF(ISNUMBER(SEARCH(SETTINGS!$K$5,D12)),SETTINGS!$L$5,IF(ISNUMBER(SEARCH(SETTINGS!$K$6,D12)),SETTINGS!$L$6,IF(ISNUMBER(SEARCH(SETTINGS!$K$7,D12)),SETTINGS!$L$7,IF(ISNUMBER(SEARCH(SETTINGS!$K$8,D12)),SETTINGS!$L$8,IF(ISNUMBER(SEARCH(SETTINGS!$K$9,D12)),SETTINGS!$L$9,IF(ISNUMBER(SEARCH(SETTINGS!$K$10,D12)),SETTINGS!$L$10,IF(ISNUMBER(SEARCH(SETTINGS!$K$11,D12)),SETTINGS!$L$11,IF(ISNUMBER(SEARCH(SETTINGS!$K$12,D12)),SETTINGS!$L$12,IF(ISNUMBER(SEARCH(SETTINGS!$K$13,D12)),SETTINGS!$L$13,IF(ISNUMBER(SEARCH(SETTINGS!$K$14,D12)),SETTINGS!$L$14,IF(ISNUMBER(SEARCH(SETTINGS!$K$15,D12)),SETTINGS!$L$15,IF(ISNUMBER(SEARCH(SETTINGS!$K$16,D12)),SETTINGS!$L$16,IF(ISNUMBER(SEARCH(SETTINGS!$K$17,D12)),SETTINGS!$L$17,IF(ISNUMBER(SEARCH(SETTINGS!$K$18,D12)),SETTINGS!$L$18,"Miscellaneous")))))))))))))))) -> Miscellaneous | I12: =IF(B12="","",IF(G12<>"",G12,H12)) -> Food | J12: Grocery | K12: Local Market | L12: UPI-linked Bank | M12: Essential | N12: One-Time | O12: Paid | Q12: Self | R12: Not Applicable | S12: Hostel | U12: =IF(B12="","",IF(C12="Income","INC-",IF(C12="Expense","EXP-","TRX-"))&TEXT(YEAR(B12),"0000")&"-"&TEXT(ROW()-7,"0000")) -> EXP-2026-0005 | V12: =IF(B12="","",TEXT(B12,"mmmm")) -> February | W12: =IF(B12="","",MONTH(B12)) -> 2 | X12: =IF(B12="","",YEAR(B12)) -> 2026 | Y12: =IF(B12="","",DAY(B12)) -> 12 | Z12: =IF(B12="","",IF(WEEKDAY(B12,2)>5,"Weekend","Weekday")) -> Weekday | AA12: =IF(B12="","",IF(COUNTIFS($B$8:$B$1007,B12,$E$8:$E$1007,E12,$D$8:$D$1007,D12,$I$8:$I$1007,I12)>1,"Possible Duplicate","OK")) -> OK | AB12: =IF(OR(B12="",C12<>"Expense"),"",IF(E12>IFERROR(AVERAGEIFS($E$8:$E$1007,$I$8:$I$1007,I12,$C$8:$C$1007,"Expense")*SETTINGS!$B$20,0),"Unusually High","Normal")) -> Normal | AC12: Yes | AF12: =IF(A12<>"Yes","No",IF(AND(AC12="Yes",SETTINGS!$B$16="No"),"No","Yes")) -> Yes | AG12: =IF(A12<>"Yes","",IF(OR(B12="",D12="",E12<=0,F12="",I12=""),"Check Required Fields",IF(AA12="Possible Duplicate","Possible Duplicate",IF(E12>SETTINGS!$B$22,"Review Extreme Value","OK")))) -> OK
